2021-02-28 19:21:42,844 INFO: Microblog startup [in /home/alexluttrell2013/microblog/app/__init__.py:77]
2021-02-28 19:27:06,734 INFO: Microblog startup [in /home/alexluttrell2013/microblog/app/__init__.py:77]
2021-02-28 19:27:43,761 INFO: Microblog startup [in /home/alexluttrell2013/microblog/app/__init__.py:77]
2021-02-28 19:30:58,015 INFO: Microblog startup [in /home/alexluttrell2013/microblog/app/__init__.py:77]
2021-02-28 19:30:58,189 INFO: Microblog startup [in /home/alexluttrell2013/microblog/app/__init__.py:77]
2021-02-28 19:30:58,210 INFO: Microblog startup [in /home/alexluttrell2013/microblog/app/__init__.py:77]
2021-02-28 19:30:58,250 INFO: Microblog startup [in /home/alexluttrell2013/microblog/app/__init__.py:77]
2021-02-28 20:04:25,205 ERROR: Exception on /index [POST] [in /home/alexluttrell2013/microblog/venv/lib/python3.8/site-packages/flask/app.py:1891]
Traceback (most recent call last):
  File "/home/alexluttrell2013/microblog/venv/lib/python3.8/site-packages/sqlalchemy/engine/base.py", line 1276, in _execute_context
    self.dialect.do_execute(
  File "/home/alexluttrell2013/microblog/venv/lib/python3.8/site-packages/sqlalchemy/engine/default.py", line 609, in do_execute
    cursor.execute(statement, parameters)
  File "/home/alexluttrell2013/microblog/venv/lib/python3.8/site-packages/pymysql/cursors.py", line 148, in execute
    result = self._query(query)
  File "/home/alexluttrell2013/microblog/venv/lib/python3.8/site-packages/pymysql/cursors.py", line 310, in _query
    conn.query(q)
  File "/home/alexluttrell2013/microblog/venv/lib/python3.8/site-packages/pymysql/connections.py", line 548, in query
    self._affected_rows = self._read_query_result(unbuffered=unbuffered)
  File "/home/alexluttrell2013/microblog/venv/lib/python3.8/site-packages/pymysql/connections.py", line 775, in _read_query_result
    result.read()
  File "/home/alexluttrell2013/microblog/venv/lib/python3.8/site-packages/pymysql/connections.py", line 1156, in read
    first_packet = self.connection._read_packet()
  File "/home/alexluttrell2013/microblog/venv/lib/python3.8/site-packages/pymysql/connections.py", line 725, in _read_packet
    packet.raise_for_error()
  File "/home/alexluttrell2013/microblog/venv/lib/python3.8/site-packages/pymysql/protocol.py", line 221, in raise_for_error
    err.raise_mysql_exception(self._data)
  File "/home/alexluttrell2013/microblog/venv/lib/python3.8/site-packages/pymysql/err.py", line 143, in raise_mysql_exception
    raise errorclass(errno, errval)
pymysql.err.DataError: (1366, "Incorrect string value: '\\xF0\\x9F\\xA4\\x93' for column 'body' at row 1")

The above exception was the direct cause of the following exception:

Traceback (most recent call last):
  File "/home/alexluttrell2013/microblog/venv/lib/python3.8/site-packages/flask/app.py", line 2447, in wsgi_app
    response = self.full_dispatch_request()
  File "/home/alexluttrell2013/microblog/venv/lib/python3.8/site-packages/flask/app.py", line 1952, in full_dispatch_request
    rv = self.handle_user_exception(e)
  File "/home/alexluttrell2013/microblog/venv/lib/python3.8/site-packages/flask/app.py", line 1821, in handle_user_exception
    reraise(exc_type, exc_value, tb)
  File "/home/alexluttrell2013/microblog/venv/lib/python3.8/site-packages/flask/_compat.py", line 39, in reraise
    raise value
  File "/home/alexluttrell2013/microblog/venv/lib/python3.8/site-packages/flask/app.py", line 1950, in full_dispatch_request
    rv = self.dispatch_request()
  File "/home/alexluttrell2013/microblog/venv/lib/python3.8/site-packages/flask/app.py", line 1936, in dispatch_request
    return self.view_functions[rule.endpoint](**req.view_args)
  File "/home/alexluttrell2013/microblog/venv/lib/python3.8/site-packages/flask_login/utils.py", line 272, in decorated_view
    return func(*args, **kwargs)
  File "/home/alexluttrell2013/microblog/app/main/routes.py", line 35, in index
    db.session.commit()
  File "/home/alexluttrell2013/microblog/venv/lib/python3.8/site-packages/sqlalchemy/orm/scoping.py", line 163, in do
    return getattr(self.registry(), name)(*args, **kwargs)
  File "/home/alexluttrell2013/microblog/venv/lib/python3.8/site-packages/sqlalchemy/orm/session.py", line 1046, in commit
    self.transaction.commit()
  File "/home/alexluttrell2013/microblog/venv/lib/python3.8/site-packages/sqlalchemy/orm/session.py", line 504, in commit
    self._prepare_impl()
  File "/home/alexluttrell2013/microblog/venv/lib/python3.8/site-packages/sqlalchemy/orm/session.py", line 483, in _prepare_impl
    self.session.flush()
  File "/home/alexluttrell2013/microblog/venv/lib/python3.8/site-packages/sqlalchemy/orm/session.py", line 2540, in flush
    self._flush(objects)
  File "/home/alexluttrell2013/microblog/venv/lib/python3.8/site-packages/sqlalchemy/orm/session.py", line 2682, in _flush
    transaction.rollback(_capture_exception=True)
  File "/home/alexluttrell2013/microblog/venv/lib/python3.8/site-packages/sqlalchemy/util/langhelpers.py", line 68, in __exit__
    compat.raise_(
  File "/home/alexluttrell2013/microblog/venv/lib/python3.8/site-packages/sqlalchemy/util/compat.py", line 182, in raise_
    raise exception
  File "/home/alexluttrell2013/microblog/venv/lib/python3.8/site-packages/sqlalchemy/orm/session.py", line 2642, in _flush
    flush_context.execute()
  File "/home/alexluttrell2013/microblog/venv/lib/python3.8/site-packages/sqlalchemy/orm/unitofwork.py", line 422, in execute
    rec.execute(self)
  File "/home/alexluttrell2013/microblog/venv/lib/python3.8/site-packages/sqlalchemy/orm/unitofwork.py", line 586, in execute
    persistence.save_obj(
  File "/home/alexluttrell2013/microblog/venv/lib/python3.8/site-packages/sqlalchemy/orm/persistence.py", line 239, in save_obj
    _emit_insert_statements(
  File "/home/alexluttrell2013/microblog/venv/lib/python3.8/site-packages/sqlalchemy/orm/persistence.py", line 1135, in _emit_insert_statements
    result = cached_connections[connection].execute(
  File "/home/alexluttrell2013/microblog/venv/lib/python3.8/site-packages/sqlalchemy/engine/base.py", line 1011, in execute
    return meth(self, multiparams, params)
  File "/home/alexluttrell2013/microblog/venv/lib/python3.8/site-packages/sqlalchemy/sql/elements.py", line 298, in _execute_on_connection
    return connection._execute_clauseelement(self, multiparams, params)
  File "/home/alexluttrell2013/microblog/venv/lib/python3.8/site-packages/sqlalchemy/engine/base.py", line 1124, in _execute_clauseelement
    ret = self._execute_context(
  File "/home/alexluttrell2013/microblog/venv/lib/python3.8/site-packages/sqlalchemy/engine/base.py", line 1316, in _execute_context
    self._handle_dbapi_exception(
  File "/home/alexluttrell2013/microblog/venv/lib/python3.8/site-packages/sqlalchemy/engine/base.py", line 1510, in _handle_dbapi_exception
    util.raise_(
  File "/home/alexluttrell2013/microblog/venv/lib/python3.8/site-packages/sqlalchemy/util/compat.py", line 182, in raise_
    raise exception
  File "/home/alexluttrell2013/microblog/venv/lib/python3.8/site-packages/sqlalchemy/engine/base.py", line 1276, in _execute_context
    self.dialect.do_execute(
  File "/home/alexluttrell2013/microblog/venv/lib/python3.8/site-packages/sqlalchemy/engine/default.py", line 609, in do_execute
    cursor.execute(statement, parameters)
  File "/home/alexluttrell2013/microblog/venv/lib/python3.8/site-packages/pymysql/cursors.py", line 148, in execute
    result = self._query(query)
  File "/home/alexluttrell2013/microblog/venv/lib/python3.8/site-packages/pymysql/cursors.py", line 310, in _query
    conn.query(q)
  File "/home/alexluttrell2013/microblog/venv/lib/python3.8/site-packages/pymysql/connections.py", line 548, in query
    self._affected_rows = self._read_query_result(unbuffered=unbuffered)
  File "/home/alexluttrell2013/microblog/venv/lib/python3.8/site-packages/pymysql/connections.py", line 775, in _read_query_result
    result.read()
  File "/home/alexluttrell2013/microblog/venv/lib/python3.8/site-packages/pymysql/connections.py", line 1156, in read
    first_packet = self.connection._read_packet()
  File "/home/alexluttrell2013/microblog/venv/lib/python3.8/site-packages/pymysql/connections.py", line 725, in _read_packet
    packet.raise_for_error()
  File "/home/alexluttrell2013/microblog/venv/lib/python3.8/site-packages/pymysql/protocol.py", line 221, in raise_for_error
    err.raise_mysql_exception(self._data)
  File "/home/alexluttrell2013/microblog/venv/lib/python3.8/site-packages/pymysql/err.py", line 143, in raise_mysql_exception
    raise errorclass(errno, errval)
sqlalchemy.exc.DataError: (pymysql.err.DataError) (1366, "Incorrect string value: '\\xF0\\x9F\\xA4\\x93' for column 'body' at row 1")
[SQL: INSERT INTO post (body, timestamp, user_id, language) VALUES (%(body)s, %(timestamp)s, %(user_id)s, %(language)s)]
[parameters: {'body': 'HOOTY-HOO NERDS ðŸ¤“', 'timestamp': datetime.datetime(2021, 2, 28, 20, 4, 25, 203795), 'user_id': 1, 'language': ''}]
(Background on this error at: http://sqlalche.me/e/13/9h9h)
